2019-08-16 08:33:44,953 [ERROR]  Exception occurred while handling uri: 'http://localhost:5005/webhook'
Traceback (most recent call last):
  File "/home/hackathon/.conda/envs/rasa2/lib/python3.6/site-packages/sanic/app.py", line 893, in handle_request
    handler, args, kwargs, uri = self.router.get(request)
  File "/home/hackathon/.conda/envs/rasa2/lib/python3.6/site-packages/sanic/router.py", line 407, in get
    return self._get(request.path, request.method, "")
  File "/home/hackathon/.conda/envs/rasa2/lib/python3.6/site-packages/sanic/router.py", line 469, in _get
    raise NotFound("Requested URL {} not found".format(url))
sanic.exceptions.NotFound: Requested URL /webhook not found
